Unable to init server: Could not connect: Connection refused
Unable to init server: Could not connect: Connection refused

(transfer_attacks.py:3690800): Gdk-CRITICAL **: 11:56:19.022: gdk_cursor_new_for_display: assertion 'GDK_IS_DISPLAY (display)' failed
Using cache found in /home/naddeok5/.cache/torch/hub/chenyaofo_pytorch-cifar-models_master
Using cache found in /home/naddeok5/.cache/torch/hub/chenyaofo_pytorch-cifar-models_master
Batches Done...:   0%|          | 0/40 [00:00<?, ?it/s]Files already downloaded and verified
Files already downloaded and verified
Working on OSSA Attacks...
Batches Done...:   0%|          | 0/40 [00:04<?, ?it/s]
Begin Lancoz
Iteration:  0 	Similarity:  0.0009982187766581774
Iteration:  1 	Similarity:  0.8937785029411316
Iteration:  2 	Similarity:  0.9729501008987427
Iteration:  3 	Similarity:  0.9866721034049988
Iteration:  4 	Similarity:  0.9918417930603027
Traceback (most recent call last):
  File "transfer_attacks.py", line 59, in <module>
    ossa_accs  = attacker.get_OSSA_attack_accuracy(epsilons = epsilons)                                          
  File "/home/naddeok5/FIM/adversarial_attacks.py", line 257, in get_OSSA_attack_accuracy
    attacks = (inputs.view(batch_size, 1, 28*28) + perturbations).view(batch_size, 1, 28, 28)
RuntimeError: shape '[256, 1, 784]' is invalid for input of size 786432
