Unable to init server: Could not connect: Connection refused
Unable to init server: Could not connect: Connection refused

(transfer_attacks.py:3700779): Gdk-CRITICAL **: 12:11:54.922: gdk_cursor_new_for_display: assertion 'GDK_IS_DISPLAY (display)' failed
Using cache found in /home/naddeok5/.cache/torch/hub/chenyaofo_pytorch-cifar-models_master
Using cache found in /home/naddeok5/.cache/torch/hub/chenyaofo_pytorch-cifar-models_master
Batches Done...:   0%|          | 0/40 [00:00<?, ?it/s]Files already downloaded and verified
Files already downloaded and verified
Working on OSSA Attacks...
Batches Done...:   2%|▎         | 1/40 [00:05<03:24,  5.24s/it]Batches Done...:   5%|▌         | 2/40 [00:09<03:04,  4.85s/it]Batches Done...:   8%|▊         | 3/40 [00:14<02:55,  4.73s/it]Batches Done...:  10%|█         | 4/40 [00:18<02:48,  4.67s/it]Batches Done...:  12%|█▎        | 5/40 [00:23<02:42,  4.63s/it]Batches Done...:  15%|█▌        | 6/40 [00:28<02:37,  4.62s/it]Batches Done...:  18%|█▊        | 7/40 [00:32<02:32,  4.61s/it]Batches Done...:  20%|██        | 8/40 [00:37<02:27,  4.61s/it]Batches Done...:  22%|██▎       | 9/40 [00:41<02:22,  4.61s/it]