Unable to init server: Could not connect: Connection refused
Unable to init server: Could not connect: Connection refused

(wandb_model_trainer.py:2302879): Gdk-CRITICAL **: 12:09:56.744: gdk_cursor_new_for_display: assertion 'GDK_IS_DISPLAY (display)' failed
429 response executing GraphQL.
{"error":"rate limit exceeded"}

429 response executing GraphQL.
{"error":"rate limit exceeded"}

wandb: Agent Starting Run: 58qh3i3i with config:
wandb: 	batch_size: 9
wandb: 	criterion: cross_entropy
wandb: 	epochs: 150
wandb: 	learning_rate: 0.01326271790658393
wandb: 	model_name: cifar10_mobilenetv2_x1_4
wandb: 	momentum: 0.9
wandb: 	optimizer: nesterov
wandb: 	pretrained: False
wandb: 	scheduler: Cosine Annealing
wandb: 	transformation: models/pretrained/U_w_means_0-005174736492335796_n0-0014449692098423839_n0-0010137659264728427_and_stds_1-130435824394226_1-128873586654663_1-1922636032104492_.pt
wandb: 	use_SAM: True
wandb: 	weight_decay: 1e-05
wandb: Currently logged in as: naddeok (use `wandb login --relogin` to force relogin)
Files already downloaded and verified
Files already downloaded and verified
CIFAR10 is Loaded
Create sweep with ID: db53cnlf
Sweep URL: https://wandb.ai/naddeok/CIFAR10/sweeps/db53cnlf
2021-05-26 12:10:04.785617: I tensorflow/stream_executor/platform/default/dso_loader.cc:49] Successfully opened dynamic library libcudart.so.11.0
2021-05-26 12:10:04.787636: I tensorflow/stream_executor/platform/default/dso_loader.cc:49] Successfully opened dynamic library libcudart.so.11.0
wandb: Tracking run with wandb version 0.10.30
wandb: Syncing run effortless-sweep-1
wandb: ‚≠êÔ∏è View project at https://wandb.ai/naddeok/CIFAR10
wandb: üßπ View sweep at https://wandb.ai/naddeok/CIFAR10/sweeps/db53cnlf
wandb: üöÄ View run at https://wandb.ai/naddeok/CIFAR10/runs/58qh3i3i
wandb: Run data is saved locally in /home/naddeok5/FIM/wandb/run-20210526_121003-58qh3i3i
wandb: Run `wandb offline` to turn off syncing.
wandb: Waiting for W&B process to finish, PID 2303073
wandb: Program failed with code 1.  Press ctrl-c to abort syncing.
wandb: - 0.00MB of 0.00MB uploaded (0.00MB deduped)wandb: \ 0.00MB of 0.00MB uploaded (0.00MB deduped)wandb: | 0.00MB of 0.01MB uploaded (0.00MB deduped)wandb: / 0.01MB of 0.01MB uploaded (0.00MB deduped)wandb: - 0.01MB of 0.01MB uploaded (0.00MB deduped)wandb: \ 0.01MB of 0.01MB uploaded (0.00MB deduped)wandb: | 0.01MB of 0.01MB uploaded (0.00MB deduped)wandb: / 0.01MB of 0.01MB uploaded (0.00MB deduped)wandb: - 0.01MB of 0.01MB uploaded (0.00MB deduped)wandb:                                                                                
429 response executing GraphQL.
{"error":"rate limit exceeded"}

wandb: Find user logs for this run at: /home/naddeok5/FIM/wandb/run-20210526_121003-58qh3i3i/logs/debug.log
wandb: Find internal logs for this run at: /home/naddeok5/FIM/wandb/run-20210526_121003-58qh3i3i/logs/debug-internal.log
wandb: Run summary:
wandb:   Data Augmentation False
wandb:            _runtime 3
wandb:          _timestamp 1622045406
wandb:               _step 0
wandb: Run history:
wandb:   Data Augmentation ‚ñÅ
wandb:            _runtime ‚ñÅ
wandb:          _timestamp ‚ñÅ
wandb:               _step ‚ñÅ
wandb: 
wandb: Synced 4 W&B file(s), 0 media file(s), 0 artifact file(s) and 0 other file(s)
wandb: 
wandb: Synced effortless-sweep-1: https://wandb.ai/naddeok/CIFAR10/runs/58qh3i3i
Run 58qh3i3i errored: RuntimeError('CUDA error: out of memory')
wandb: ERROR Run 58qh3i3i errored: RuntimeError('CUDA error: out of memory')
429 response executing GraphQL.
{"error":"rate limit exceeded"}

429 response executing GraphQL.
{"error":"rate limit exceeded"}

Retry attempt failed:
Traceback (most recent call last):
  File "/home/naddeok5/.local/lib/python3.8/site-packages/wandb/sdk/lib/retry.py", line 102, in __call__
    result = self._call_fn(*args, **kwargs)
  File "/home/naddeok5/.local/lib/python3.8/site-packages/wandb/sdk/internal/internal_api.py", line 133, in execute
    six.reraise(*sys.exc_info())
  File "/usr/lib/python3/dist-packages/six.py", line 703, in reraise
    raise value
  File "/home/naddeok5/.local/lib/python3.8/site-packages/wandb/sdk/internal/internal_api.py", line 127, in execute
    return self.client.execute(*args, **kwargs)
  File "/home/naddeok5/.local/lib/python3.8/site-packages/wandb/vendor/gql-0.2.0/gql/client.py", line 52, in execute
    result = self._get_result(document, *args, **kwargs)
  File "/home/naddeok5/.local/lib/python3.8/site-packages/wandb/vendor/gql-0.2.0/gql/client.py", line 60, in _get_result
    return self.transport.execute(document, *args, **kwargs)
  File "/home/naddeok5/.local/lib/python3.8/site-packages/wandb/vendor/gql-0.2.0/gql/transport/requests.py", line 39, in execute
    request.raise_for_status()
  File "/usr/lib/python3/dist-packages/requests/models.py", line 940, in raise_for_status
    raise HTTPError(http_error_msg, response=self)
requests.exceptions.HTTPError: 429 Client Error: Too Many Requests for url: https://api.wandb.ai/graphql
wandb: Network error (HTTPError), entering retry loop.
wandb: Sweep Agent: Waiting for job.
wandb: Job received.
wandb: Agent Starting Run: rpcwaqre with config:
wandb: 	batch_size: 11
wandb: 	criterion: cross_entropy
wandb: 	epochs: 150
wandb: 	learning_rate: 0.01665551957133289
wandb: 	model_name: cifar10_mobilenetv2_x1_4
wandb: 	momentum: 0.9
wandb: 	optimizer: nesterov
wandb: 	pretrained: False
wandb: 	scheduler: Cosine Annealing
wandb: 	transformation: models/pretrained/U_w_means_0-005174736492335796_n0-0014449692098423839_n0-0010137659264728427_and_stds_1-130435824394226_1-128873586654663_1-1922636032104492_.pt
wandb: 	use_SAM: True
wandb: 	weight_decay: 1e-05

signal only works in main thread

2021-05-26 12:10:21.757040: I tensorflow/stream_executor/platform/default/dso_loader.cc:49] Successfully opened dynamic library libcudart.so.11.0
2021-05-26 12:10:21.759753: I tensorflow/stream_executor/platform/default/dso_loader.cc:49] Successfully opened dynamic library libcudart.so.11.0
wandb: Tracking run with wandb version 0.10.30
wandb: Syncing run spring-sweep-2
wandb: ‚≠êÔ∏è View project at https://wandb.ai/naddeok/CIFAR10
wandb: üßπ View sweep at https://wandb.ai/naddeok/CIFAR10/sweeps/db53cnlf
wandb: üöÄ View run at https://wandb.ai/naddeok/CIFAR10/runs/rpcwaqre
wandb: Run data is saved locally in /home/naddeok5/FIM/wandb/run-20210526_121019-rpcwaqre
wandb: Run `wandb offline` to turn off syncing.
wandb: Waiting for W&B process to finish, PID 2303351
wandb: Program failed with code 1.  Press ctrl-c to abort syncing.
wandb: - 0.00MB of 0.00MB uploaded (0.00MB deduped)wandb: \ 0.00MB of 0.00MB uploaded (0.00MB deduped)wandb: | 0.00MB of 0.00MB uploaded (0.00MB deduped)wandb: / 0.00MB of 0.01MB uploaded (0.00MB deduped)wandb: - 0.00MB of 0.01MB uploaded (0.00MB deduped)wandb: \ 0.01MB of 0.01MB uploaded (0.00MB deduped)wandb: | 0.01MB of 0.01MB uploaded (0.00MB deduped)wandb: / 0.01MB of 0.01MB uploaded (0.00MB deduped)wandb: - 0.01MB of 0.01MB uploaded (0.00MB deduped)wandb: \ 0.01MB of 0.01MB uploaded (0.00MB deduped)wandb:                                                                                
wandb: Find user logs for this run at: /home/naddeok5/FIM/wandb/run-20210526_121019-rpcwaqre/logs/debug.log
wandb: Find internal logs for this run at: /home/naddeok5/FIM/wandb/run-20210526_121019-rpcwaqre/logs/debug-internal.log
wandb: Run summary:
wandb:   Data Augmentation False
wandb:            _runtime 4
wandb:          _timestamp 1622045423
wandb:               _step 0
wandb: Run history:
wandb:   Data Augmentation ‚ñÅ
wandb:            _runtime ‚ñÅ
wandb:          _timestamp ‚ñÅ
wandb:               _step ‚ñÅ
wandb: 
wandb: Synced 4 W&B file(s), 0 media file(s), 0 artifact file(s) and 0 other file(s)
wandb: 
wandb: Synced spring-sweep-2: https://wandb.ai/naddeok/CIFAR10/runs/rpcwaqre
Run rpcwaqre errored: RuntimeError('CUDA error: out of memory')
wandb: ERROR Run rpcwaqre errored: RuntimeError('CUDA error: out of memory')
wandb: Agent Starting Run: 9ma6k9ft with config:
wandb: 	batch_size: 28
wandb: 	criterion: cross_entropy
wandb: 	epochs: 150
wandb: 	learning_rate: 0.09419798714869534
wandb: 	model_name: cifar10_mobilenetv2_x1_4
wandb: 	momentum: 0.9
wandb: 	optimizer: nesterov
wandb: 	pretrained: False
wandb: 	scheduler: Cosine Annealing
wandb: 	transformation: models/pretrained/U_w_means_0-005174736492335796_n0-0014449692098423839_n0-0010137659264728427_and_stds_1-130435824394226_1-128873586654663_1-1922636032104492_.pt
wandb: 	use_SAM: True
wandb: 	weight_decay: 1e-05

signal only works in main thread

2021-05-26 12:10:30.358311: I tensorflow/stream_executor/platform/default/dso_loader.cc:49] Successfully opened dynamic library libcudart.so.11.0
2021-05-26 12:10:30.360464: I tensorflow/stream_executor/platform/default/dso_loader.cc:49] Successfully opened dynamic library libcudart.so.11.0
wandb: Tracking run with wandb version 0.10.30
wandb: Syncing run fluent-sweep-3
wandb: ‚≠êÔ∏è View project at https://wandb.ai/naddeok/CIFAR10
wandb: üßπ View sweep at https://wandb.ai/naddeok/CIFAR10/sweeps/db53cnlf
wandb: üöÄ View run at https://wandb.ai/naddeok/CIFAR10/runs/9ma6k9ft
wandb: Run data is saved locally in /home/naddeok5/FIM/wandb/run-20210526_121028-9ma6k9ft
wandb: Run `wandb offline` to turn off syncing.
wandb: Waiting for W&B process to finish, PID 2303546
wandb: Program failed with code 1.  Press ctrl-c to abort syncing.
wandb: - 0.00MB of 0.00MB uploaded (0.00MB deduped)wandb: \ 0.00MB of 0.00MB uploaded (0.00MB deduped)wandb: | 0.00MB of 0.01MB uploaded (0.00MB deduped)wandb: / 0.00MB of 0.01MB uploaded (0.00MB deduped)wandb: - 0.01MB of 0.01MB uploaded (0.00MB deduped)wandb: \ 0.01MB of 0.01MB uploaded (0.00MB deduped)wandb: | 0.01MB of 0.01MB uploaded (0.00MB deduped)wandb: / 0.01MB of 0.01MB uploaded (0.00MB deduped)wandb: - 0.01MB of 0.01MB uploaded (0.00MB deduped)wandb:                                                                                
wandb: Find user logs for this run at: /home/naddeok5/FIM/wandb/run-20210526_121028-9ma6k9ft/logs/debug.log
wandb: Find internal logs for this run at: /home/naddeok5/FIM/wandb/run-20210526_121028-9ma6k9ft/logs/debug-internal.log
wandb: Run summary:
wandb:   Data Augmentation False
wandb:            _runtime 3
wandb:          _timestamp 1622045431
wandb:               _step 0
wandb: Run history:
wandb:   Data Augmentation ‚ñÅ
wandb:            _runtime ‚ñÅ
wandb:          _timestamp ‚ñÅ
wandb:               _step ‚ñÅ
wandb: 
wandb: Synced 4 W&B file(s), 0 media file(s), 0 artifact file(s) and 0 other file(s)
wandb: 
wandb: Synced fluent-sweep-3: https://wandb.ai/naddeok/CIFAR10/runs/9ma6k9ft
Run 9ma6k9ft errored: RuntimeError('CUDA error: out of memory')
wandb: ERROR Run 9ma6k9ft errored: RuntimeError('CUDA error: out of memory')
Detected 3 failed runs in the first 60 seconds, killing sweep.
wandb: ERROR Detected 3 failed runs in the first 60 seconds, killing sweep.
wandb: To disable this check set WANDB_AGENT_DISABLE_FLAPPING=true

signal only works in main thread

