wandb: Currently logged in as: naddeok (use `wandb login --relogin` to force relogin)
wandb: wandb version 0.12.9 is available!  To upgrade, please run:
wandb:  $ pip install wandb --upgrade
2022-01-10 11:04:20.323979: I tensorflow/stream_executor/platform/default/dso_loader.cc:48] Successfully opened dynamic library libcudart.so.10.2
2022-01-10 11:04:20.328675: I tensorflow/stream_executor/platform/default/dso_loader.cc:48] Successfully opened dynamic library libcudart.so.10.2
wandb: Tracking run with wandb version 0.12.3
wandb: Syncing run classic-pond-22
wandb:  View project at https://wandb.ai/naddeok/DDP%20LSR%20CIFAR10
wandb:  View run at https://wandb.ai/naddeok/DDP%20LSR%20CIFAR10/runs/spov5dss
wandb: Run data is saved locally in /home/naddeok5/FIM/wandb/run-20220110_110418-spov5dss
wandb: Run `wandb offline` to turn off syncing.
Augmenting Training Data on Rank  1
Files already downloaded and verified
Files already downloaded and verified
Augmenting Training Data on Rank  2
Files already downloaded and verified
Files already downloaded and verified

Augmenting Training Data on Rank  0
Files already downloaded and verifiProcess SpawnProcess-2:
Traceback (most recent call last):
  File "/home/naddeok5/.local/lib/python3.8/site-packages/torch/multiprocessing/spawn.py", line 59, in _wrap
    fn(i, *args)
  File "/home/naddeok5/FIM/ddp_model_trainer.py", line 149, in train
    run = setup(rank, world_size, config, project_name)
  File "/home/naddeok5/FIM/ddp_model_trainer.py", line 42, in setup
    dist.init_process_group(backend    = "nccl",
  File "/home/naddeok5/.local/lib/python3.8/site-packages/torch/distributed/distributed_c10d.py", line 534, in init_process_group
    store, rank, world_size = next(rendezvous_iterator)
  File "/home/naddeok5/.local/lib/python3.8/site-packages/torch/distributed/rendezvous.py", line 230, in _env_rendezvous_handler
    store = _create_c10d_store(master_addr, master_port, rank, world_size, timeout)
  File "/home/naddeok5/.local/lib/python3.8/site-packages/torch/distributed/rendezvous.py", line 158, in _create_c10d_store
    return TCPStore(
RuntimeError: connect() timed out.

During handling of the above exception, another exception occurred:

Traceback (most recent call last):
  File "/usr/lib/python3.8/multiprocessing/process.py", line 315, in _bootstrap
    self.run()
  File "/usr/lib/python3.8/multiprocessing/process.py", line 108, in run
    self._target(*self._args, **self._kwargs)
  File "/home/naddeok5/.local/lib/python3.8/site-packages/torch/multiprocessing/spawn.py", line 59, in _wrap
    fn(i, *args)
KeyboardInterrupt
erIter.__del__ at 0x7fb2fd88cee0>
Traceback (most recent call last):
  File "/home/naddeok5/.local/lib/python3.8/site-packages/torch/utils/data/dataloader.py", line 1328, in __del__
    self._shutdown_workers()
  File "/home/naddeok5/.local/lib/python3.8/site-packages/torch/utils/data/dataloader.py", line 1301, in _shutdown_workers
    w.join(timeout=_utils.MP_STATUS_CHECK_INTERVAL)
  File "/usr/lib/python3.8/multiprocessing/process.py", line 149, in join
    res = self._popen.wait(timeout)
  File "/usr/lib/python3.8/multiprocessing/popen_fork.py", line 44, in wait
    if not wait([self.sentinel], timeout):
  File "/usr/lib/python3.8/multiprocessing/connection.py", line 930, in wait
    ready = selector.select(timeout)
  File "/usr/lib/python3.8/selectors.py", line 415, in select
    fd_event_list = self._selector.poll(timeout)
KeyboardInterrupt: 
Exception ignored in: <function _MultiProcessingDataLoaderIter.__del__ at 0x7f8a8d862ee0>
Traceback (most recent call last):
  File "/home/naddeok5/.local/lib/python3.8/site-packages/torch/utils/data/dataloader.py", line 1328, in __del__
    self._shutdown_workers()
  File "/home/naddeok5/.local/lib/python3.8/site-packages/torch/utils/data/dataloader.py", line 1301, in _shutdown_workers
    w.join(timeout=_utils.MP_STATUS_CHECK_INTERVAL)
  File "/usr/lib/python3.8/multiprocessing/process.py", line 149, in join
    res = self._popen.wait(timeout)
  File "/usr/lib/python3.8/multiprocessing/popen_fork.py", line 44, in wait
    if not wait([self.sentinel], timeout):
  File "/usr/lib/python3.8/multiprocessing/connection.py", line 930, in wait
    ready = selector.select(timeout)
  File "/usr/lib/python3.8/selectors.py", line 415, in select
    fd_event_list = self._selector.poll(timeout)
KeyboardInterrupt: 
Exception ignored in: <function _MultiProcessingDataLoaderIter.__del__ at 0x7f86d8ec1ee0>
Traceback (most recent call last):
  File "/home/naddeok5/.local/lib/python3.8/site-packages/torch/utils/data/dataloader.py", line 1328, in __del__
    self._shutdown_workers()
  File "/home/naddeok5/.local/lib/python3.8/site-packages/torch/utils/data/dataloader.py", line 1301, in _shutdown_workers
    w.join(timeout=_utils.MP_STATUS_CHECK_INTERVAL)
  File "/usr/lib/python3.8/multiprocessing/process.py", line 149, in join
    res = self._popen.wait(timeout)
  File "/usr/lib/python3.8/multiprocessing/popen_fork.py", line 44, in wait
    if not wait([self.sentinel], timeout):
  File "/usr/lib/python3.8/multiprocessing/connection.py", line 930, in wait
    ready = selector.select(timeout)
  File "/usr/lib/python3.8/selectors.py", line 415, in select
    fd_event_list = self._selector.poll(timeout)
KeyboardInterrupt: 
Process SpawnProcess-1:
Traceback (most recent call last):
  File "/usr/lib/python3.8/multiprocessing/process.py", line 318, in _bootstrap
    util._exit_function()
  File "/usr/lib/python3.8/multiprocessing/util.py", line 334, in _exit_function
    p.join()
  File "/usr/lib/python3.8/multiprocessing/process.py", line 149, in join
    res = self._popen.wait(timeout)
  File "/usr/lib/python3.8/multiprocessing/popen_fork.py", line 47, in wait
    return self.poll(os.WNOHANG if timeout == 0.0 else 0)
  File "/usr/lib/python3.8/multiprocessing/popen_fork.py", line 27, in poll
    pid, sts = os.waitpid(self.pid, flag)
KeyboardInterrupt

During handling of the above exception, another exception occurred:

Traceback (most recent call last):
  File "<string>", line 1, in <module>
  File "/usr/lib/python3.8/multiprocessing/spawn.py", line 116, in spawn_main
    exitcode = _main(fd, parent_sentinel)
  File "/usr/lib/python3.8/multiprocessing/spawn.py", line 129, in _main
    return self._bootstrap(parent_sentinel)
  File "/usr/lib/python3.8/multiprocessing/process.py", line 331, in _bootstrap
    traceback.print_exc()
  File "/usr/lib/python3.8/traceback.py", line 163, in print_exc
    print_exception(*sys.exc_info(), limit=limit, file=file, chain=chain)
  File "/usr/lib/python3.8/traceback.py", line 103, in print_exception
    for line in TracebackException(
  File "/usr/lib/python3.8/traceback.py", line 468, in __init__
    def __init__(self, exc_type, exc_value, exc_traceback, *, limit=None,
KeyboardInterrupt
Traceback (most recent call last):
  File "/usr/lib/python3.8/multiprocessing/process.py", line 318, in _bootstrap
    util._exit_function()
  File "/usr/lib/python3.8/multiprocessing/util.py", line 334, in _exit_function
    p.join()
  File "/usr/lib/python3.8/multiprocessing/process.py", line 149, in join
    res = self._popen.wait(timeout)
  File "/usr/lib/python3.8/multiprocessing/popen_fork.py", line 47, in wait
    return self.poll(os.WNOHANG if timeout == 0.0 else 0)
  File "/usr/lib/python3.8/multiprocessing/popen_fork.py", line 27, in poll
    pid, sts = os.waitpid(self.pid, flag)
KeyboardInterrupt

During handling of the above exception, another exception occurred:

Traceback (most recent call last):
  File "<string>", line 1, in <module>
  File "/usr/lib/python3.8/multiprocessing/spawn.py", line 116, in spawn_main
    exitcode = _main(fd, parent_sentinel)
  File "/usr/lib/python3.8/multiprocessing/spawn.py", line 129, in _main
    return self._bootstrap(parent_sentinel)
  File "/usr/lib/python3.8/multiprocessing/process.py", line 331, in _bootstrap
    traceback.print_exc()
  File "/usr/lib/python3.8/traceback.py", line 163, in print_exc
    print_exception(*sys.exc_info(), limit=limit, file=file, chain=chain)
  File "/usr/lib/python3.8/traceback.py", line 103, in print_exception
    for line in TracebackException(
  File "/usr/lib/python3.8/traceback.py", line 468, in __init__
    def __init__(self, exc_type, exc_value, exc_traceback, *, limit=None,
KeyboardInterrupt
wandb: Waiting for W&B process to finish, PID 731092... (failed 255). Press ctrl-c to abort syncing.
Process wandb_internal:
Traceback (most recent call last):
  File "/usr/lib/python3.8/multiprocessing/process.py", line 315, in _bootstrap
    self.run()
  File "/usr/lib/python3.8/multiprocessing/process.py", line 108, in run
    self._target(*self._args, **self._kwargs)
  File "/home/naddeok5/.local/lib/python3.8/site-packages/wandb/sdk/internal/internal.py", line 152, in wandb_internal
    thread.join()
  File "/usr/lib/python3.8/threading.py", line 1011, in join
    self._wait_for_tstate_lock()
  File "/usr/lib/python3.8/threading.py", line 1027, in _wait_for_tstate_lock
    elif lock.acquire(block, timeout):
KeyboardInterrupt
Error in atexit._run_exitfuncs:
Traceback (most recent call last):
  File "/home/naddeok5/.local/lib/python3.8/site-packages/wandb/sdk/wandb_run.py", line 1629, in _atexit_cleanup
    self._on_finish()
  File "/home/naddeok5/.local/lib/python3.8/site-packages/wandb/sdk/wandb_run.py", line 1805, in _on_finish
    self._poll_exit_response = self._wait_for_finish()
  File "/home/naddeok5/.local/lib/python3.8/site-packages/wandb/sdk/wandb_run.py", line 1745, in _wait_for_finish
    poll_exit_resp = self._backend.interface.communicate_poll_exit()
  File "/home/naddeok5/.local/lib/python3.8/site-packages/wandb/sdk/interface/interface.py", line 777, in communicate_poll_exit
    result = self._communicate(rec)
  File "/home/naddeok5/.local/lib/python3.8/site-packages/wandb/sdk/interface/interface.py", line 539, in _communicate
    return self._communicate_async(rec, local=local).get(timeout=timeout)
  File "/home/naddeok5/.local/lib/python3.8/site-packages/wandb/sdk/interface/interface.py", line 544, in _communicate_async
    raise Exception("The wandb backend process has shutdown")
Exception: The wandb backend process has shutdown

During handling of the above exception, another exception occurred:

Traceback (most recent call last):
  File "/home/naddeok5/.local/lib/python3.8/site-packages/wandb/sdk/wandb_run.py", line 1638, in _atexit_cleanup
    self._backend.cleanup()
  File "/home/naddeok5/.local/lib/python3.8/site-packages/wandb/sdk/backend/backend.py", line 167, in cleanup
    self.interface.join()
  File "/home/naddeok5/.local/lib/python3.8/site-packages/wandb/sdk/interface/interface.py", line 830, in join
    _ = self._communicate(record)
  File "/home/naddeok5/.local/lib/python3.8/site-packages/wandb/sdk/interface/interface.py", line 539, in _communicate
    return self._communicate_async(rec, local=local).get(timeout=timeout)
  File "/home/naddeok5/.local/lib/python3.8/site-packages/wandb/sdk/interface/interface.py", line 544, in _communicate_async
    raise Exception("The wandb backend process has shutdown")
Exception: The wandb backend process has shutdown

